<?xml version="1.0"?>
<!--
  Dog2 Robot Description (Xacro Source)
  
  This file defines the Dog2 quadruped robot with parameterized joint limits.
  All configuration is in this single file for simplicity.
  
  JOINT LIMITS (Current: continuous, will be converted to revolute):
  - Hip joints (j11, j21, j31, j41): Currently continuous (360° unlimited)
    * Target: ±150° (±2.618 rad) for obstacle crossing
    * 0°: Leg vertical (default stance)
    * +90°: Leg forward (climbing phase)
    * -90°: Leg backward (retraction phase)
    * ±150°: Extreme folding for morphing
  
  - Knee joints (j111, j211, j311, j411): Currently continuous (360° unlimited)
    * Target: ±160° (±2.8 rad) for bidirectional folding
    * 0°: Leg straight (singularity point during morphing)
    * -160°: Elbow configuration (shin behind thigh)
    * +160°: Knee configuration (shin in front of thigh)
    * WARNING: 0° is a singularity - controller must handle carefully
  
  MODIFYING LIMITS:
  1. Edit the properties section at the top of this file
  2. Run: colcon build packages-select dog2_description
  3. Verify: python3 scripts validate_urdf_limits.py urdf/dog2.urdf
  
  OBSTACLE CROSSING PHASES:
  - Phase 1 (Approach): Hip 0° to +45°, knee -90° (elbow)
  - Phase 2 (Climb): Hip +45° to +90°, knee -90° to 0° (straightening)
  - Phase 3 (Morph): Hip +90°, knee 0° to +90° (elbow → knee transition)
  - Phase 4 (Descend): Hip +90° to 0°, knee +90° (knee configuration)
  
  Generated from: dog2.urdf (backup: dog2.urdf.backup_xacro_migration)
  Migration Date: 2026-01-26
-->
<robot xmlns:xacro="http://www.ros.org/wiki/xacro" name="dog2">

  <!-- ============================================ -->
  <!-- SECTION 1: PROPERTY DEFINITIONS              -->
  <!-- ============================================ -->
  
  <!-- Hip joint limits: ±150° (±2.618 rad) for obstacle crossing
       NOW ACTIVE - Joints converted from continuous to revolute -->
  <xacro:property name="hip_lower_limit" value="-2.618"/>
  <xacro:property name="hip_upper_limit" value="2.618"/>
  <xacro:property name="hip_effort" value="50"/>
  <xacro:property name="hip_velocity" value="20"/>

  <!-- Knee joint limits: ±160° (±2.8 rad) for bidirectional folding
       NOW ACTIVE - Joints converted from continuous to revolute -->
  <xacro:property name="knee_lower_limit" value="-2.8"/>
  <xacro:property name="knee_upper_limit" value="2.8"/>
  <xacro:property name="knee_effort" value="50"/>
  <xacro:property name="knee_velocity" value="20"/>

  <!-- Prismatic joint limits (unchanged from original URDF) -->
  <xacro:property name="prismatic_effort" value="100"/>
  <xacro:property name="prismatic_velocity" value="5"/>

  <link
    name="world"/>
  
  <joint
    name="world_joint"
    type="fixed">
    <parent
      link="world"/>
    <child
      link="base_link"/>
    <origin
      xyz="0 0 0"
      rpy="0 0 0"/>
  </joint>

  <link
    name="base_link">
    <inertial>
      <origin
        xyz="1.2272 -0.7470 0.2649"
        rpy="1.5708 0 0" />
      <mass
        value="6.0" />
      <!-- 调整惯性值：按质量比例缩放 (缩放因子 0.306) -->
      <inertia
        ixx="0.0153"
        ixy="0.00011"
        ixz="0"
        iyy="0.052"
        iyz="0"
        izz="0.044" />
    </inertial>
    <visual>
      <origin
        xyz="0 0 0"
        rpy="0 0 0" />
      <geometry>
        <mesh
          filename="package://dog2_description/meshes/base_link.STL" />
      </geometry>
      <material
        name="">
        <color
          rgba="0.752941176470588 0.752941176470588 0.752941176470588 1" />
      </material>
    </visual>
    <collision>
      <origin
        xyz="0 0 0"
        rpy="0 0 0" />
      <geometry>
        <mesh
          filename="package://dog2_description/meshes/base_link.STL" />
      </geometry>
    </collision>
  </link>
  <!-- ============================================ -->
  <!-- SECTION 2: LEG MACRO DEFINITION              -->
  <!-- ============================================ -->
  
  <xacro:macro name="leg" params="leg_num origin_xyz origin_rpy prismatic_lower prismatic_upper">
  <link
    name="l${leg_num}">
    <inertial>
      <origin
        xyz="-0.0159999123716776 0.000737036465389251 0.0261570925915838"
        rpy="0 0 0" />
      <mass
        value="0.3" />
      <inertia
        ixx="0.000107100908138004"
        ixy="0"
        ixz="0"
        iyy="8.38648309010005E-05"
        iyz="0"
        izz="7.86994452918461E-05" />
    </inertial>
    <visual>
      <origin
        xyz="0 0 0"
        rpy="0 0 0" />
      <geometry>
        <mesh
          filename="package://dog2_description/meshes/l${leg_num}.STL" />
      </geometry>
      <material
        name="">
        <color
          rgba="1 1 1 1" />
      </material>
    </visual>
    <collision>
      <origin
        xyz="0 0 0"
        rpy="0 0 0" />
      <geometry>
        <mesh
          filename="package://dog2_description/meshes/l${leg_num}.STL" />
      </geometry>
    </collision>
  </link>
  <joint
    name="j${leg_num}"
    type="prismatic">
    <origin
      xyz="1.1026 -0.80953 0.2649"
      rpy="1.5708 0 0" />
    <parent
      link="base_link" />
    <child
      link="l${leg_num}" />
    <axis
      xyz="-1 0 0" />
    <!-- 修复：速度限制从 1 m/s 提升到 5 m/s，适配 MPC/WBC 快速响应 -->
    <limit
      lower="${prismatic_lower}"
      upper="${prismatic_upper}"
      effort="${prismatic_effort}"
      velocity="${prismatic_velocity}" />
  </joint>
  <link
    name="l${leg_num}1">
    <inertial>
      <origin
        xyz="-0.0233000000000003 -0.038305456702832 0.000879463367713051"
        rpy="0 0 0" />
      <mass
        value="0.25" />
      <!-- 修复：惯性值从 1E-10 改为合理值 1E-4，避免物理仿真爆炸 -->
      <inertia
        ixx="0.0001"
        ixy="0"
        ixz="0"
        iyy="0.0001"
        iyz="0"
        izz="0.0001" />
    </inertial>
    <visual>
      <origin
        xyz="0 0 0"
        rpy="0 0 0" />
      <geometry>
        <mesh
          filename="package://dog2_description/meshes/l${leg_num}1.STL" />
      </geometry>
      <material
        name="">
        <color
          rgba="0.266666666666667 0.529411764705882 1 1" />
      </material>
    </visual>
    <collision>
      <origin
        xyz="0 0 0"
        rpy="0 0 0" />
      <geometry>
        <mesh
          filename="package://dog2_description/meshes/l${leg_num}1.STL" />
      </geometry>
    </collision>
  </link>
  <joint
    name="j${leg_num}1"
    type="revolute">
    <origin
      xyz="-0.016 0.0199 0.055"
      rpy="0 0 1.5708" />
    <parent
      link="l${leg_num}" />
    <child
      link="l${leg_num}1" />
    <axis
      xyz="-1 0 0" />
    <!-- Hip joint: ±150° (±2.618 rad) for obstacle crossing -->
    <limit
      lower="${hip_lower_limit}"
      upper="${hip_upper_limit}"
      effort="${hip_effort}"
      velocity="${hip_velocity}" />
  </joint>
  <link
    name="l${leg_num}11">
    <inertial>
      <origin
        xyz="0.026 -0.0760041259902766 0.0649874821212071"
        rpy="0 0 0" />
      <mass
        value="0.4" />
      <!-- 调整惯性：保持原始量级但调整比例使其更细长 -->
      <inertia
        ixx="0.000666"
        ixy="0"
        ixz="0"
        iyy="0.000356"
        iyz="0.000266"
        izz="0.000534" />
    </inertial>
    <visual>
      <origin
        xyz="0 0 0"
        rpy="0 0 0" />
      <geometry>
        <mesh
          filename="package://dog2_description/meshes/l${leg_num}11.STL" />
      </geometry>
      <material
        name="">
        <color
          rgba="1 1 1 1" />
      </material>
    </visual>
    <collision>
      <origin
        xyz="0 0 0"
        rpy="0 0 0" />
      <geometry>
        <mesh
          filename="package://dog2_description/meshes/l${leg_num}11.STL" />
      </geometry>
    </collision>
  </link>
  <joint
    name="j${leg_num}11"
    type="revolute">
    <origin
      xyz="-0.0233 -0.055 0.0274"
      rpy="1.5708 1.5708 0" />
    <parent
      link="l${leg_num}1" />
    <child
      link="l${leg_num}11" />
    <axis
      xyz="-1 0 0" />
    <!-- Knee joint: ±160° (±2.8 rad) for bidirectional folding -->
    <limit
      lower="${knee_lower_limit}"
      upper="${knee_upper_limit}"
      effort="${knee_effort}"
      velocity="${knee_velocity}" />
  </joint>
  <link
    name="l${leg_num}111">
    <inertial>
      <origin
        xyz="0.0254901816398352 -0.143524743603395 -0.0694046953395906"
        rpy="0 0 0" />
      <mass
        value="0.5" />
      <inertia
        ixx="0.004517"
        ixy="0.00000870"
        ixz="0.00000420"
        iyy="0.000975"
        iyz="-0.00176971"
        izz="0.003666" />
    </inertial>
    <visual>
      <origin
        xyz="0 0 0"
        rpy="0 0 0" />
      <geometry>
        <mesh
          filename="package://dog2_description/meshes/l${leg_num}111.STL" />
      </geometry>
      <material
        name="">
        <color
          rgba="1 1 1 1" />
      </material>
    </visual>
    <collision>
      <origin
        xyz="0 0 0"
        rpy="0 0 0" />
      <geometry>
        <mesh
          filename="package://dog2_description/meshes/l${leg_num}111.STL" />
      </geometry>
    </collision>
  </link>
  <joint
    name="j${leg_num}111"
    type="fixed">
    <origin
      xyz="0 -0.15201 0.12997"
      rpy="0 0 0" />
    <parent
      link="l${leg_num}11" />
    <child
      link="l${leg_num}111" />
  </joint>


  <!-- Gazebo friction configuration for foot link -->
  <!-- Prevents "ice skating" bug by adding proper ground friction -->
  <gazebo reference="l${leg_num}111">
    <mu1>1.0</mu1>  <!-- Friction coefficient in primary direction -->
    <mu2>1.0</mu2>  <!-- Friction coefficient in secondary direction -->
    <kp>1000000.0</kp>  <!-- Contact stiffness -->
    <kd>100.0</kd>  <!-- Contact damping -->
    <minDepth>0.001</minDepth>  <!-- Minimum penetration before contact -->
    <maxVel>0.1</maxVel>  <!-- Maximum contact correction velocity -->
    <material>Gazebo/Grey</material>
  </gazebo>

  </xacro:macro>

  <!-- ============================================ -->
  <!-- SECTION 3: LEG INSTANTIATIONS                -->
  <!-- ============================================ -->
  
  <!-- Leg 1: Front Right -->
  <xacro:leg leg_num="1" 
             origin_xyz="1.1026 -0.80953 0.2649" 
             origin_rpy="1.5708 0 0" 
             prismatic_lower="-0.111" 
             prismatic_upper="0.111"/>
  
  <!-- Leg 2: Front Left -->
  <xacro:leg leg_num="2" 
             origin_xyz="1.3491 -0.80953 0.2649" 
             origin_rpy="1.5708 0 0" 
             prismatic_lower="-0.111" 
             prismatic_upper="0.111"/>
  
  <!-- Leg 3: Rear Left -->
  <xacro:leg leg_num="3" 
             origin_xyz="1.3491 -0.68953 0.2649" 
             origin_rpy="1.5708 0 -3.1416" 
             prismatic_lower="-0.111" 
             prismatic_upper="0.111"/>
  
  <!-- Leg 4: Rear Right -->
  <xacro:leg leg_num="4" 
             origin_xyz="1.1071 -0.68953 0.2649" 
             origin_rpy="1.5708 0 -3.1416" 
             prismatic_lower="-0.111" 
             prismatic_upper="0.111"/>

  <!-- ============================================ -->
  <!-- SECTION 4: ROS 2 CONTROL & GAZEBO            -->
  <!-- ============================================ -->

  <ros2_control name="GazeboSystem" type="system">
    <hardware>
      <plugin>gazebo_ros2_control/GazeboSystem</plugin>
    </hardware>
    
    <!-- Leg 1 Joints -->
    <joint name="j1">
      <command_interface name="effort"/>
      <command_interface name="position"/>
      <state_interface name="position"/>
      <state_interface name="velocity"/>
      <state_interface name="effort"/>
    </joint>
    <joint name="j11">
      <command_interface name="effort"/>
      <command_interface name="position"/>
      <state_interface name="position"/>
      <state_interface name="velocity"/>
      <state_interface name="effort"/>
    </joint>
    <joint name="j111">
      <command_interface name="effort"/>
      <command_interface name="position"/>
      <state_interface name="position"/>
      <state_interface name="velocity"/>
      <state_interface name="effort"/>
    </joint>

    <!-- Leg 2 Joints -->
    <joint name="j2">
      <command_interface name="effort"/>
      <command_interface name="position"/>
      <state_interface name="position"/>
      <state_interface name="velocity"/>
      <state_interface name="effort"/>
    </joint>
    <joint name="j21">
      <command_interface name="effort"/>
      <command_interface name="position"/>
      <state_interface name="position"/>
      <state_interface name="velocity"/>
      <state_interface name="effort"/>
    </joint>
    <joint name="j211">
      <command_interface name="effort"/>
      <command_interface name="position"/>
      <state_interface name="position"/>
      <state_interface name="velocity"/>
      <state_interface name="effort"/>
    </joint>

    <!-- Leg 3 Joints -->
    <joint name="j3">
      <command_interface name="effort"/>
      <command_interface name="position"/>
      <state_interface name="position"/>
      <state_interface name="velocity"/>
      <state_interface name="effort"/>
    </joint>
    <joint name="j31">
      <command_interface name="effort"/>
      <command_interface name="position"/>
      <state_interface name="position"/>
      <state_interface name="velocity"/>
      <state_interface name="effort"/>
    </joint>
    <joint name="j311">
      <command_interface name="effort"/>
      <command_interface name="position"/>
      <state_interface name="position"/>
      <state_interface name="velocity"/>
      <state_interface name="effort"/>
    </joint>

    <!-- Leg 4 Joints -->
    <joint name="j4">
      <command_interface name="effort"/>
      <command_interface name="position"/>
      <state_interface name="position"/>
      <state_interface name="velocity"/>
      <state_interface name="effort"/>
    </joint>
    <joint name="j41">
      <command_interface name="effort"/>
      <command_interface name="position"/>
      <state_interface name="position"/>
      <state_interface name="velocity"/>
      <state_interface name="effort"/>
    </joint>
    <joint name="j411">
      <command_interface name="effort"/>
      <command_interface name="position"/>
      <state_interface name="position"/>
      <state_interface name="velocity"/>
      <state_interface name="effort"/>
    </joint>
  </ros2_control>

  <!-- Gazebo ROS 2 Control Plugin -->
  <gazebo>
    <plugin filename="libgazebo_ros2_control.so" name="gazebo_ros2_control">
      <parameters>$(find dog2_description)/config/ros2_controllers.yaml</parameters>
      <robot_param>robot_description</robot_param>
      <robot_param_node>robot_state_publisher</robot_param_node>
    </plugin>
  </gazebo>
</robot>
