<?xml version="1.0"?>
<!-- This URDF was automatically created by SolidWorks to URDF Exporter! Originally created by Stephen Brawner (brawner@gmail.com) 
     Commit Version: 1.6.0-4-g7f85cfe  Build Version: 1.6.7995.38578
     For more information, please see http://wiki.ros.org/sw_urdf_exporter -->
<robot
  name="dog2">
  <link
    name="world"/>
  
  <joint
    name="world_joint"
    type="fixed">
    <parent
      link="world"/>
    <child
      link="base_link"/>
    <origin
      xyz="0 0 0"
      rpy="0 0 0"/>
  </joint>

  <link
    name="base_link">
    <inertial>
      <origin
        xyz="1.2272 -0.7470 0.2649"
        rpy="1.5708 0 0" />
      <mass
        value="6.0" />
      <!-- 调整惯性值：按质量比例缩放 (缩放因子 0.306) -->
      <inertia
        ixx="0.0153"
        ixy="0.00011"
        ixz="0"
        iyy="0.052"
        iyz="0"
        izz="0.044" />
    </inertial>
    <visual>
      <origin
        xyz="0 0 0"
        rpy="0 0 0" />
      <geometry>
        <mesh
          filename="package://dog2_description/meshes/base_link.STL" />
      </geometry>
      <material
        name="">
        <color
          rgba="0.752941176470588 0.752941176470588 0.752941176470588 1" />
      </material>
    </visual>
    <collision>
      <origin
        xyz="0 0 0"
        rpy="0 0 0" />
      <geometry>
        <mesh
          filename="package://dog2_description/meshes/base_link.STL" />
      </geometry>
    </collision>
  </link>
  <link
    name="l1">
    <inertial>
      <origin
        xyz="-0.0159999123716776 0.000737036465389251 0.0261570925915838"
        rpy="0 0 0" />
      <mass
        value="0.3" />
      <inertia
        ixx="0.000107100908138004"
        ixy="0"
        ixz="0"
        iyy="8.38648309010005E-05"
        iyz="0"
        izz="7.86994452918461E-05" />
    </inertial>
    <visual>
      <origin
        xyz="0 0 0"
        rpy="0 0 0" />
      <geometry>
        <mesh
          filename="package://dog2_description/meshes/l1.STL" />
      </geometry>
      <material
        name="">
        <color
          rgba="1 1 1 1" />
      </material>
    </visual>
    <collision>
      <origin
        xyz="0 0 0"
        rpy="0 0 0" />
      <geometry>
        <mesh
          filename="package://dog2_description/meshes/l1.STL" />
      </geometry>
    </collision>
  </link>
  <joint
    name="j1"
    type="prismatic">
    <origin
      xyz="1.1026 -0.80953 0.2649"
      rpy="1.5708 0 0" />
    <parent
      link="base_link" />
    <child
      link="l1" />
    <axis
      xyz="-1 0 0" />
    <!-- 修复：速度限制从 1 m/s 提升到 5 m/s，适配 MPC/WBC 快速响应 -->
    <limit
      lower="-0.111"
      upper="0.008"
      effort="100"
      velocity="5" />
  </joint>
  <link
    name="l11">
    <inertial>
      <origin
        xyz="-0.0233000000000003 -0.038305456702832 0.000879463367713051"
        rpy="0 0 0" />
      <mass
        value="0.25" />
      <!-- 修复：惯性值从 1E-10 改为合理值 1E-4，避免物理仿真爆炸 -->
      <inertia
        ixx="0.0001"
        ixy="0"
        ixz="0"
        iyy="0.0001"
        iyz="0"
        izz="0.0001" />
    </inertial>
    <visual>
      <origin
        xyz="0 0 0"
        rpy="0 0 0" />
      <geometry>
        <mesh
          filename="package://dog2_description/meshes/l11.STL" />
      </geometry>
      <material
        name="">
        <color
          rgba="0.266666666666667 0.529411764705882 1 1" />
      </material>
    </visual>
    <collision>
      <origin
        xyz="0 0 0"
        rpy="0 0 0" />
      <geometry>
        <mesh
          filename="package://dog2_description/meshes/l11.STL" />
      </geometry>
    </collision>
  </link>
  <joint
    name="j11"
    type="continuous">
    <origin
      xyz="-0.016 0.0199 0.055"
      rpy="0 0 1.5708" />
    <parent
      link="l1" />
    <child
      link="l11" />
    <axis
      xyz="-1 0 0" />
    <!-- 添加：continuous 关节也需要速度和力矩限制，适配 MPC/WBC -->
    <limit
      effort="50"
      velocity="20" />
  </joint>
  <link
    name="l111">
    <inertial>
      <origin
        xyz="0.026 -0.0760041259902766 0.0649874821212071"
        rpy="0 0 0" />
      <mass
        value="0.4" />
      <!-- 调整惯性：保持原始量级但调整比例使其更细长 -->
      <inertia
        ixx="0.000666"
        ixy="0"
        ixz="0"
        iyy="0.000356"
        iyz="0.000266"
        izz="0.000534" />
    </inertial>
    <visual>
      <origin
        xyz="0 0 0"
        rpy="0 0 0" />
      <geometry>
        <mesh
          filename="package://dog2_description/meshes/l111.STL" />
      </geometry>
      <material
        name="">
        <color
          rgba="1 1 1 1" />
      </material>
    </visual>
    <collision>
      <origin
        xyz="0 0 0"
        rpy="0 0 0" />
      <geometry>
        <mesh
          filename="package://dog2_description/meshes/l111.STL" />
      </geometry>
    </collision>
  </link>
  <joint
    name="j111"
    type="continuous">
    <origin
      xyz="-0.0233 -0.055 0.0274"
      rpy="1.5708 1.5708 0" />
    <parent
      link="l11" />
    <child
      link="l111" />
    <axis
      xyz="-1 0 0" />
    <!-- 添加：continuous 关节也需要速度和力矩限制，适配 MPC/WBC -->
    <limit
      effort="50"
      velocity="20" />
  </joint>
  <link
    name="l1111">
    <inertial>
      <origin
        xyz="0.0254901816398352 -0.143524743603395 -0.0694046953395906"
        rpy="0 0 0" />
      <mass
        value="0.5" />
      <inertia
        ixx="0.004517"
        ixy="0.00000870"
        ixz="0.00000420"
        iyy="0.000975"
        iyz="-0.00176971"
        izz="0.003666" />
    </inertial>
    <visual>
      <origin
        xyz="0 0 0"
        rpy="0 0 0" />
      <geometry>
        <mesh
          filename="package://dog2_description/meshes/l1111.STL" />
      </geometry>
      <material
        name="">
        <color
          rgba="1 1 1 1" />
      </material>
    </visual>
    <collision>
      <origin
        xyz="0 0 0"
        rpy="0 0 0" />
      <geometry>
        <mesh
          filename="package://dog2_description/meshes/l1111.STL" />
      </geometry>
    </collision>
  </link>
  <joint
    name="j1111"
    type="fixed">
    <origin
      xyz="0 -0.15201 0.12997"
      rpy="0 0 0" />
    <parent
      link="l111" />
    <child
      link="l1111" />
  </joint>
  <link
    name="l2">
    <inertial>
      <origin
        xyz="0.0159999123717034 0.000737036465382368 0.0261570929046457"
        rpy="0 0 0" />
      <mass
        value="0.3" />
      <inertia
        ixx="0.000107100908138004"
        ixy="0"
        ixz="0"
        iyy="8.38648309010005E-05"
        iyz="0"
        izz="7.86994452918462E-05" />
    </inertial>
    <visual>
      <origin
        xyz="0 0 0"
        rpy="0 0 0" />
      <geometry>
        <mesh
          filename="package://dog2_description/meshes/l2.STL" />
      </geometry>
      <material
        name="">
        <color
          rgba="0.247058823529412 0.525490196078431 1 1" />
      </material>
    </visual>
    <collision>
      <origin
        xyz="0 0 0"
        rpy="0 0 0" />
      <geometry>
        <mesh
          filename="package://dog2_description/meshes/l2.STL" />
      </geometry>
    </collision>
  </link>
  <joint
    name="j2"
    type="prismatic">
    <origin
      xyz="1.3491 -0.80953 0.2649"
      rpy="1.5708 0 0" />
    <parent
      link="base_link" />
    <child
      link="l2" />
    <axis
      xyz="-1 0 0" />
    <!-- 修复：速度限制从 1 m/s 提升到 5 m/s，适配 MPC/WBC 快速响应 -->
    <limit
      lower="-0.008"
      upper="0.111"
      effort="100"
      velocity="5" />
  </joint>
  <link
    name="l21">
    <inertial>
      <origin
        xyz="-0.0233000000000007 -0.0427054567028338 8.88178419700125E-16"
        rpy="0 0 0" />
      <mass
        value="0.25" />
      <!-- 修复：惯性值从 1E-10 改为合理值 1E-4，避免物理仿真爆炸 -->
      <inertia
        ixx="0.0001"
        ixy="0"
        ixz="0"
        iyy="0.0001"
        iyz="0"
        izz="0.0001" />
    </inertial>
    <visual>
      <origin
        xyz="0 0 0"
        rpy="0 0 0" />
      <geometry>
        <mesh
          filename="package://dog2_description/meshes/l21.STL" />
      </geometry>
      <material
        name="">
        <color
          rgba="0.266666666666667 0.529411764705882 1 1" />
      </material>
    </visual>
    <collision>
      <origin
        xyz="0 0 0"
        rpy="0 0 0" />
      <geometry>
        <mesh
          filename="package://dog2_description/meshes/l21.STL" />
      </geometry>
    </collision>
  </link>
  <joint
    name="j21"
    type="continuous">
    <origin
      xyz="0.0116 0.0199 0.055"
      rpy="0 0 1.5708" />
    <parent
      link="l2" />
    <child
      link="l21" />
    <axis
      xyz="-1 0 0" />
    <!-- 添加：continuous 关节也需要速度和力矩限制，适配 MPC/WBC -->
    <limit
      effort="50"
      velocity="20" />
  </joint>
  <link
    name="l211">
    <inertial>
      <origin
        xyz="0.0260000000000001 -0.0760041259902766 0.0649874821212069"
        rpy="0 0 0" />
      <mass
        value="0.4" />
      <!-- 调整惯性：保持原始量级但调整比例使其更细长 -->
      <inertia
        ixx="0.000666"
        ixy="0"
        ixz="0"
        iyy="0.000356"
        iyz="0.000266"
        izz="0.000534" />
    </inertial>
    <visual>
      <origin
        xyz="0 0 0"
        rpy="0 0 0" />
      <geometry>
        <mesh
          filename="package://dog2_description/meshes/l211.STL" />
      </geometry>
      <material
        name="">
        <color
          rgba="1 1 1 1" />
      </material>
    </visual>
    <collision>
      <origin
        xyz="0 0 0"
        rpy="0 0 0" />
      <geometry>
        <mesh
          filename="package://dog2_description/meshes/l211.STL" />
      </geometry>
    </collision>
  </link>
  <joint
    name="j211"
    type="continuous">
    <origin
      xyz="-0.0233 -0.0594 0.0264"
      rpy="1.5708 1.5708 0" />
    <parent
      link="l21" />
    <child
      link="l211" />
    <axis
      xyz="-1 0 0" />
    <!-- 添加：continuous 关节也需要速度和力矩限制，适配 MPC/WBC -->
    <limit
      effort="50"
      velocity="20" />
  </joint>
  <link
    name="l2111">
    <inertial>
      <origin
        xyz="0.0254901816398352 -0.143524743603395 -0.069404695339591"
        rpy="0 0 0" />
      <mass
        value="0.5" />
      <inertia
        ixx="0.004517"
        ixy="0.00000870"
        ixz="0.00000420"
        iyy="0.000975"
        iyz="-0.00176971"
        izz="0.003666" />
    </inertial>
    <visual>
      <origin
        xyz="0 0 0"
        rpy="0 0 0" />
      <geometry>
        <mesh
          filename="package://dog2_description/meshes/l2111.STL" />
      </geometry>
      <material
        name="">
        <color
          rgba="0.333333333333333 0.333333333333333 0.333333333333333 1" />
      </material>
    </visual>
    <collision>
      <origin
        xyz="0 0 0"
        rpy="0 0 0" />
      <geometry>
        <mesh
          filename="package://dog2_description/meshes/l2111.STL" />
      </geometry>
    </collision>
  </link>
  <joint
    name="j2111"
    type="fixed">
    <origin
      xyz="0 -0.15201 0.12997"
      rpy="0 0 0" />
    <parent
      link="l211" />
    <child
      link="l2111" />
  </joint>
  <link
    name="l3">
    <inertial>
      <origin
        xyz="-0.0160000876283128 0.000737036465387864 0.0261570929046675"
        rpy="0 0 0" />
      <mass
        value="0.3" />
      <inertia
        ixx="0.000107100908138004"
        ixy="0"
        ixz="0"
        iyy="8.38648309010006E-05"
        iyz="0"
        izz="7.86994452918464E-05" />
    </inertial>
    <visual>
      <origin
        xyz="0 0 0"
        rpy="0 0 0" />
      <geometry>
        <mesh
          filename="package://dog2_description/meshes/l3.STL" />
      </geometry>
      <material
        name="">
        <color
          rgba="0.247058823529412 0.525490196078431 1 1" />
      </material>
    </visual>
    <collision>
      <origin
        xyz="0 0 0"
        rpy="0 0 0" />
      <geometry>
        <mesh
          filename="package://dog2_description/meshes/l3.STL" />
      </geometry>
    </collision>
  </link>
  <joint
    name="j3"
    type="prismatic">
    <origin
      xyz="1.3491 -0.68953 0.2649"
      rpy="1.5708 0 -3.1416" />
    <parent
      link="base_link" />
    <child
      link="l3" />
    <axis
      xyz="-1 0 0" />
    <!-- 修复：速度限制从 1 m/s 提升到 5 m/s，适配 MPC/WBC 快速响应 -->
    <limit
      lower="-0.111"
      upper="0.008"
      effort="100"
      velocity="5" />
  </joint>
  <link
    name="l31">
    <inertial>
      <origin
        xyz="-0.0232999999999994 -0.0383054567028329 0.000879463367712385"
        rpy="0 0 0" />
      <mass
        value="0.25" />
      <!-- 修复：惯性值从 1E-10 改为合理值 1E-4，避免物理仿真爆炸 -->
      <inertia
        ixx="0.0001"
        ixy="0"
        ixz="0"
        iyy="0.0001"
        iyz="0"
        izz="0.0001" />
    </inertial>
    <visual>
      <origin
        xyz="0 0 0"
        rpy="0 0 0" />
      <geometry>
        <mesh
          filename="package://dog2_description/meshes/l31.STL" />
      </geometry>
      <material
        name="">
        <color
          rgba="0.266666666666667 0.529411764705882 1 1" />
      </material>
    </visual>
    <collision>
      <origin
        xyz="0 0 0"
        rpy="0 0 0" />
      <geometry>
        <mesh
          filename="package://dog2_description/meshes/l31.STL" />
      </geometry>
    </collision>
  </link>
  <joint
    name="j31"
    type="continuous">
    <origin
      xyz="-0.016 0.0199 0.055"
      rpy="3.1416 0 1.5708" />
    <parent
      link="l3" />
    <child
      link="l31" />
    <axis
      xyz="-1 0 0" />
    <!-- 添加：continuous 关节也需要速度和力矩限制，适配 MPC/WBC -->
    <limit
      effort="50"
      velocity="20" />
  </joint>
  <link
    name="l311">
    <inertial>
      <origin
        xyz="-0.0259999999999999 -0.0760041259902766 0.0649874821212069"
        rpy="0 0 0" />
      <mass
        value="0.4" />
      <!-- 调整惯性：保持原始量级但调整比例使其更细长 -->
      <inertia
        ixx="0.000666"
        ixy="0"
        ixz="0"
        iyy="0.000356"
        iyz="0.000266"
        izz="0.000534" />
    </inertial>
    <visual>
      <origin
        xyz="0 0 0"
        rpy="0 0 0" />
      <geometry>
        <mesh
          filename="package://dog2_description/meshes/l311.STL" />
      </geometry>
      <material
        name="">
        <color
          rgba="1 1 1 1" />
      </material>
    </visual>
    <collision>
      <origin
        xyz="0 0 0"
        rpy="0 0 0" />
      <geometry>
        <mesh
          filename="package://dog2_description/meshes/l311.STL" />
      </geometry>
    </collision>
  </link>
  <joint
    name="j311"
    type="continuous">
    <origin
      xyz="-0.0233 -0.055 -0.0254"
      rpy="1.5708 1.5708 0" />
    <parent
      link="l31" />
    <child
      link="l311" />
    <axis
      xyz="-1 0 0" />
    <!-- 添加：continuous 关节也需要速度和力矩限制，适配 MPC/WBC -->
    <limit
      effort="50"
      velocity="20" />
  </joint>
  <link
    name="l3111">
    <inertial>
      <origin
        xyz="-0.0265098183601649 -0.143524743603395 -0.0694046953395908"
        rpy="0 0 0" />
      <mass
        value="0.5" />
      <inertia
        ixx="0.004517"
        ixy="0.00000870"
        ixz="0.00000420"
        iyy="0.000975"
        iyz="-0.00176971"
        izz="0.003666" />
    </inertial>
    <visual>
      <origin
        xyz="0 0 0"
        rpy="0 0 0" />
      <geometry>
        <mesh
          filename="package://dog2_description/meshes/l3111.STL" />
      </geometry>
      <material
        name="">
        <color
          rgba="1 1 1 1" />
      </material>
    </visual>
    <collision>
      <origin
        xyz="0 0 0"
        rpy="0 0 0" />
      <geometry>
        <mesh
          filename="package://dog2_description/meshes/l3111.STL" />
      </geometry>
    </collision>
  </link>
  <joint
    name="j3111"
    type="fixed">
    <origin
      xyz="0 -0.15201 0.12997"
      rpy="0 0 0" />
    <parent
      link="l311" />
    <child
      link="l3111" />
  </joint>
  <link
    name="l4">
    <inertial>
      <!-- 修正：与l2对称，x应为正值 -->
      <origin
        xyz="0.0160000876283128 0.000737036465387864 0.0261570929046675"
        rpy="0 0 0" />
      <mass
        value="0.3" />
      <inertia
        ixx="0.000107100908138004"
        ixy="0"
        ixz="0"
        iyy="8.38648309010006E-05"
        iyz="0"
        izz="7.86994452918464E-05" />
    </inertial>
    <visual>
      <origin
        xyz="0 0 0"
        rpy="0 0 0" />
      <geometry>
        <mesh
          filename="package://dog2_description/meshes/l4.STL" />
      </geometry>
      <material
        name="">
        <color
          rgba="1 1 1 1" />
      </material>
    </visual>
    <collision>
      <origin
        xyz="0 0 0"
        rpy="0 0 0" />
      <geometry>
        <mesh
          filename="package://dog2_description/meshes/l4.STL" />
      </geometry>
    </collision>
  </link>
  <joint
    name="j4"
    type="prismatic">
    <origin
      xyz="1.1071 -0.68953 0.2649"
      rpy="1.5708 0 -3.1416" />
    <parent
      link="base_link" />
    <child
      link="l4" />
    <axis
      xyz="-1 0 0" />
    <!-- 修复：速度限制从 1 m/s 提升到 5 m/s，适配 MPC/WBC 快速响应 -->
    <limit
      lower="-0.008"
      upper="0.111"
      effort="100"
      velocity="5" />
  </joint>
  <link
    name="l41">
    <inertial>
      <origin
        xyz="-0.0233 -0.038305 0.00087946"
        rpy="0 0 0" />
      <mass
        value="0.25" />
      <!-- 修复：惯性值从 1E-10 改为合理值 1E-4，避免物理仿真爆炸 -->
      <inertia
        ixx="0.0001"
        ixy="0"
        ixz="0"
        iyy="0.0001"
        iyz="0"
        izz="0.0001" />
    </inertial>
    <visual>
      <origin
        xyz="0 0 0"
        rpy="0 0 0" />
      <geometry>
        <mesh
          filename="package://dog2_description/meshes/l41.STL" />
      </geometry>
      <material
        name="">
        <color
          rgba="0.26667 0.52941 1 1" />
      </material>
    </visual>
    <collision>
      <origin
        xyz="0 0 0"
        rpy="0 0 0" />
      <geometry>
        <mesh
          filename="package://dog2_description/meshes/l41.STL" />
      </geometry>
    </collision>
  </link>
  <joint
    name="j41"
    type="continuous">
    <origin
      xyz="0.0116 0.0199 0.055"
      rpy="3.1416 0 1.5708" />
    <parent
      link="l4" />
    <child
      link="l41" />
    <axis
      xyz="-1 0 0" />
    <!-- 添加：continuous 关节也需要速度和力矩限制，适配 MPC/WBC -->
    <limit
      effort="50"
      velocity="20" />
  </joint>
  <link
    name="l411">
    <inertial>
      <!-- 修正：左前腿，x应为-0.026，z应为正值0.065 -->
      <origin
        xyz="-0.026 -0.0760041259902766 0.0649874821212069"
        rpy="0 0 0" />
      <mass
        value="0.4" />
      <!-- 调整惯性：保持原始量级但调整比例使其更细长 -->
      <inertia
        ixx="0.000666"
        ixy="0"
        ixz="0"
        iyy="0.000356"
        iyz="0.000266"
        izz="0.000534" />
    </inertial>
    <visual>
      <origin
        xyz="0 0 0"
        rpy="0 3.1416 0" />
      <geometry>
        <mesh
          filename="package://dog2_description/meshes/l411.STL" />
      </geometry>
      <material
        name="">
        <color
          rgba="1 1 1 1" />
      </material>
    </visual>
    <collision>
      <origin
        xyz="0 0 0"
        rpy="0 3.1416 0" />
      <geometry>
        <mesh
          filename="package://dog2_description/meshes/l411.STL" />
      </geometry>
    </collision>
  </link>
  <joint
    name="j411"
    type="continuous">
    <origin
      xyz="-0.0233 -0.055 -0.0254"
      rpy="1.5708 1.5708 0" />
    <parent
      link="l41" />
    <child
      link="l411" />
    <axis
      xyz="-1 0 0" />
    <!-- 添加：continuous 关节也需要速度和力矩限制，适配 MPC/WBC -->
    <limit
      effort="50"
      velocity="20" />
  </joint>
  <link
    name="l4111">
    <inertial>
      <origin
        xyz="-0.02651 -0.14352 -0.069405"
        rpy="0 0 0" />
      <mass
        value="0.5" />
      <inertia
        ixx="0.004517"
        ixy="0.00000870"
        ixz="0.00000420"
        iyy="0.000975"
        iyz="-0.00221215"
        izz="0.003666" />
    </inertial>
    <visual>
      <origin
        xyz="0 0 0"
        rpy="0 0 0" />
      <geometry>
        <mesh
          filename="package://dog2_description/meshes/l4111.STL" />
      </geometry>
      <material
        name="">
        <color
          rgba="0.33333 0.33333 0.33333 1" />
      </material>
    </visual>
    <collision>
      <origin
        xyz="0 0 0"
        rpy="0 0 0" />
      <geometry>
        <mesh
          filename="package://dog2_description/meshes/l4111.STL" />
      </geometry>
    </collision>
  </link>
  <joint
    name="j4111"
    type="fixed">
    <origin
      xyz="0 -0.15201 0.12997"
      rpy="0 0 0" />
    <parent
      link="l411" />
    <child
      link="l4111" />
  </joint>

  <!-- ROS 2 Control Configuration -->
  <ros2_control name="GazeboSystem" type="system">
    <hardware>
      <plugin>gazebo_ros2_control/GazeboSystem</plugin>
    </hardware>
    
    <!-- Leg 1 Joints -->
    <joint name="j1">
      <command_interface name="effort"/>
      <command_interface name="position"/>
      <state_interface name="position"/>
      <state_interface name="velocity"/>
      <state_interface name="effort"/>
    </joint>
    <joint name="j11">
      <command_interface name="effort"/>
      <command_interface name="position"/>
      <state_interface name="position"/>
      <state_interface name="velocity"/>
      <state_interface name="effort"/>
    </joint>
    <joint name="j111">
      <command_interface name="effort"/>
      <command_interface name="position"/>
      <state_interface name="position"/>
      <state_interface name="velocity"/>
      <state_interface name="effort"/>
    </joint>

    <!-- Leg 2 Joints -->
    <joint name="j2">
      <command_interface name="effort"/>
      <command_interface name="position"/>
      <state_interface name="position"/>
      <state_interface name="velocity"/>
      <state_interface name="effort"/>
    </joint>
    <joint name="j21">
      <command_interface name="effort"/>
      <command_interface name="position"/>
      <state_interface name="position"/>
      <state_interface name="velocity"/>
      <state_interface name="effort"/>
    </joint>
    <joint name="j211">
      <command_interface name="effort"/>
      <command_interface name="position"/>
      <state_interface name="position"/>
      <state_interface name="velocity"/>
      <state_interface name="effort"/>
    </joint>

    <!-- Leg 3 Joints -->
    <joint name="j3">
      <command_interface name="effort"/>
      <command_interface name="position"/>
      <state_interface name="position"/>
      <state_interface name="velocity"/>
      <state_interface name="effort"/>
    </joint>
    <joint name="j31">
      <command_interface name="effort"/>
      <command_interface name="position"/>
      <state_interface name="position"/>
      <state_interface name="velocity"/>
      <state_interface name="effort"/>
    </joint>
    <joint name="j311">
      <command_interface name="effort"/>
      <command_interface name="position"/>
      <state_interface name="position"/>
      <state_interface name="velocity"/>
      <state_interface name="effort"/>
    </joint>

    <!-- Leg 4 Joints -->
    <joint name="j4">
      <command_interface name="effort"/>
      <command_interface name="position"/>
      <state_interface name="position"/>
      <state_interface name="velocity"/>
      <state_interface name="effort"/>
    </joint>
    <joint name="j41">
      <command_interface name="effort"/>
      <command_interface name="position"/>
      <state_interface name="position"/>
      <state_interface name="velocity"/>
      <state_interface name="effort"/>
    </joint>
    <joint name="j411">
      <command_interface name="effort"/>
      <command_interface name="position"/>
      <state_interface name="position"/>
      <state_interface name="velocity"/>
      <state_interface name="effort"/>
    </joint>
  </ros2_control>

  <!-- Gazebo ROS 2 Control Plugin -->
  <gazebo>
    <plugin filename="libgazebo_ros2_control.so" name="gazebo_ros2_control">
      <robot_param>robot_description</robot_param>
      <robot_param_node>robot_state_publisher</robot_param_node>
    </plugin>
  </gazebo>
</robot>
