<?xml version="1.0"?>
<!-- This URDF was automatically created by SolidWorks to URDF Exporter! Originally created by Stephen Brawner (brawner@gmail.com) 
     Commit Version: 1.6.0-4-g7f85cfe  Build Version: 1.6.7995.38578
     For more information, please see http://wiki.ros.org/sw_urdf_exporter -->
<robot
  name="dog2">
  <link
    name="world"/>
  
  <joint
    name="world_joint"
    type="fixed">
    <parent
      link="world"/>
    <child
      link="base_link"/>
    <origin
      xyz="0 0 0"
      rpy="0 0 0"/>
  </joint>

  <link
    name="base_link">
    <inertial>
      <origin
        xyz="1.2272 -0.7470 0.2649"
        rpy="0 0 0" />
      <mass
        value="19.5954026422848" />
      <inertia
        ixx="0.0706894969736693"
        ixy="0.000453806584174252"
        ixz="5.45956159159812E-07"
        iyy="0.224472521009215"
        iyz="-5.88183224643092E-08"
        izz="0.194898420480141" />
    </inertial>
    <visual>
      <origin
        xyz="0 0 0"
        rpy="0 0 0" />
      <geometry>
        <mesh
          filename="package://panda_description/meshes/base_link.STL" />
      </geometry>
      <material
        name="">
        <color
          rgba="0.752941176470588 0.752941176470588 0.752941176470588 1" />
      </material>
    </visual>
    <collision>
      <origin
        xyz="0 0 0"
        rpy="0 0 0" />
      <geometry>
        <mesh
          filename="package://panda_description/meshes/base_link.STL" />
      </geometry>
    </collision>
  </link>
  <link
    name="l1">
    <inertial>
      <origin
        xyz="-0.0159999123716776 0.000737036465389251 0.0261570925915838"
        rpy="0 0 0" />
      <mass
        value="0.512324909923602" />
      <inertia
        ixx="0.000107100908138004"
        ixy="0"
        ixz="0"
        iyy="8.38648309010005E-05"
        iyz="0"
        izz="7.86994452918461E-05" />
    </inertial>
    <visual>
      <origin
        xyz="0 0 0"
        rpy="0 0 0" />
      <geometry>
        <mesh
          filename="package://panda_description/meshes/l1.STL" />
      </geometry>
      <material
        name="">
        <color
          rgba="1 1 1 1" />
      </material>
    </visual>
    <collision>
      <origin
        xyz="0 0 0"
        rpy="0 0 0" />
      <geometry>
        <mesh
          filename="package://panda_description/meshes/l1.STL" />
      </geometry>
    </collision>
  </link>
  <joint
    name="j1"
    type="prismatic">
    <origin
      xyz="1.1026 -0.80953 0.2649"
      rpy="1.5708 0 0" />
    <parent
      link="base_link" />
    <child
      link="l1" />
    <axis
      xyz="-1 0 0" />
    <limit
      lower="-0.111"
      upper="0.008"
      effort="100"
      velocity="1" />
  </joint>
  <link
    name="l11">
    <inertial>
      <origin
        xyz="-0.0233000000000003 -0.038305456702832 0.000879463367713051"
        rpy="0 0 0" />
      <mass
        value="0.346974608756836" />
      <inertia
        ixx="8.66399512887475E-05"
        ixy="3.24725100956478E-20"
        ixz="3.85561445682508E-20"
        iyy="7.91945845868074E-05"
        iyz="-5.18707927463093E-20"
        izz="7.11734259202265E-05" />
    </inertial>
    <visual>
      <origin
        xyz="0 0 0"
        rpy="0 0 0" />
      <geometry>
        <mesh
          filename="package://panda_description/meshes/l11.STL" />
      </geometry>
      <material
        name="">
        <color
          rgba="0.266666666666667 0.529411764705882 1 1" />
      </material>
    </visual>
    <collision>
      <origin
        xyz="0 0 0"
        rpy="0 0 0" />
      <geometry>
        <mesh
          filename="package://panda_description/meshes/l11.STL" />
      </geometry>
    </collision>
  </link>
  <joint
    name="j11"
    type="continuous">
    <origin
      xyz="-0.016 0.0199 0.055"
      rpy="0 0 1.5708" />
    <parent
      link="l1" />
    <child
      link="l11" />
    <axis
      xyz="-1 0 0" />
  </joint>
  <link
    name="l111">
    <inertial>
      <origin
        xyz="0.026 -0.0760041259902766 0.0649874821212071"
        rpy="0 0 0" />
      <mass
        value="0.675776067601477" />
      <inertia
        ixx="0.00243508708358432"
        ixy="1.19576912393884E-18"
        ixz="8.27103206755517E-19"
        iyy="0.00150990083615139"
        iyz="0.00115453599507958"
        izz="0.00187296482245536" />
    </inertial>
    <visual>
      <origin
        xyz="0 0 0"
        rpy="0 0 0" />
      <geometry>
        <mesh
          filename="package://panda_description/meshes/l111.STL" />
      </geometry>
      <material
        name="">
        <color
          rgba="1 1 1 1" />
      </material>
    </visual>
    <collision>
      <origin
        xyz="0 0 0"
        rpy="0 0 0" />
      <geometry>
        <mesh
          filename="package://panda_description/meshes/l111.STL" />
      </geometry>
    </collision>
  </link>
  <joint
    name="j111"
    type="continuous">
    <origin
      xyz="-0.0233 -0.055 0.0274"
      rpy="1.5708 1.5708 0" />
    <parent
      link="l11" />
    <child
      link="l111" />
    <axis
      xyz="-1 0 0" />
  </joint>
  <link
    name="l1111">
    <inertial>
      <origin
        xyz="0.0254901816398352 -0.143524743603395 -0.0694046953395906"
        rpy="0 0 0" />
      <mass
        value="1.25572837218662" />
      <inertia
        ixx="0.0112929247082815"
        ixy="2.17313539426166E-05"
        ixz="1.04994846003753E-05"
        iyy="0.0024380831661178"
        iyz="-0.00442427355366778"
        izz="0.00916575076151428" />
    </inertial>
    <visual>
      <origin
        xyz="0 0 0"
        rpy="0 0 0" />
      <geometry>
        <mesh
          filename="package://panda_description/meshes/l1111.STL" />
      </geometry>
      <material
        name="">
        <color
          rgba="1 1 1 1" />
      </material>
    </visual>
    <collision>
      <origin
        xyz="0 0 0"
        rpy="0 0 0" />
      <geometry>
        <mesh
          filename="package://panda_description/meshes/l1111.STL" />
      </geometry>
    </collision>
  </link>
  <joint
    name="j1111"
    type="continuous">
    <origin
      xyz="0 -0.15201 0.12997"
      rpy="0 0 0" />
    <parent
      link="l111" />
    <child
      link="l1111" />
    <axis
      xyz="-1 0 0" />
  </joint>
  <link
    name="l2">
    <inertial>
      <origin
        xyz="0.0159999123717034 0.000737036465382368 0.0261570929046457"
        rpy="0 0 0" />
      <mass
        value="0.512324909923602" />
      <inertia
        ixx="0.000107100908138004"
        ixy="0"
        ixz="0"
        iyy="8.38648309010005E-05"
        iyz="0"
        izz="7.86994452918462E-05" />
    </inertial>
    <visual>
      <origin
        xyz="0 0 0"
        rpy="0 0 0" />
      <geometry>
        <mesh
          filename="package://panda_description/meshes/l2.STL" />
      </geometry>
      <material
        name="">
        <color
          rgba="0.247058823529412 0.525490196078431 1 1" />
      </material>
    </visual>
    <collision>
      <origin
        xyz="0 0 0"
        rpy="0 0 0" />
      <geometry>
        <mesh
          filename="package://panda_description/meshes/l2.STL" />
      </geometry>
    </collision>
  </link>
  <joint
    name="j2"
    type="prismatic">
    <origin
      xyz="1.3491 -0.80953 0.2649"
      rpy="1.5708 0 0" />
    <parent
      link="base_link" />
    <child
      link="l2" />
    <axis
      xyz="-1 0 0" />
    <limit
      lower="-0.008"
      upper="0.111"
      effort="100"
      velocity="1" />
  </joint>
  <link
    name="l21">
    <inertial>
      <origin
        xyz="-0.0233000000000007 -0.0427054567028338 8.88178419700125E-16"
        rpy="0 0 0" />
      <mass
        value="0.346974608756837" />
      <inertia
        ixx="8.66399512887478E-05"
        ixy="2.88323459650592E-20"
        ixz="3.8481653410917E-20"
        iyy="7.91945845868078E-05"
        iyz="-2.74286155526889E-20"
        izz="7.11734259202268E-05" />
    </inertial>
    <visual>
      <origin
        xyz="0 0 0"
        rpy="0 0 0" />
      <geometry>
        <mesh
          filename="package://panda_description/meshes/l21.STL" />
      </geometry>
      <material
        name="">
        <color
          rgba="0.266666666666667 0.529411764705882 1 1" />
      </material>
    </visual>
    <collision>
      <origin
        xyz="0 0 0"
        rpy="0 0 0" />
      <geometry>
        <mesh
          filename="package://panda_description/meshes/l21.STL" />
      </geometry>
    </collision>
  </link>
  <joint
    name="j21"
    type="continuous">
    <origin
      xyz="0.0116 0.0199 0.055"
      rpy="0 0 1.5708" />
    <parent
      link="l2" />
    <child
      link="l21" />
    <axis
      xyz="-1 0 0" />
  </joint>
  <link
    name="l211">
    <inertial>
      <origin
        xyz="0.0260000000000001 -0.0760041259902766 0.0649874821212069"
        rpy="0 0 0" />
      <mass
        value="0.675776067601477" />
      <inertia
        ixx="0.00243508708358433"
        ixy="1.01068746188009E-18"
        ixz="9.40323553098713E-19"
        iyy="0.00150990083615139"
        iyz="0.00115453599507958"
        izz="0.00187296482245536" />
    </inertial>
    <visual>
      <origin
        xyz="0 0 0"
        rpy="0 0 0" />
      <geometry>
        <mesh
          filename="package://panda_description/meshes/l211.STL" />
      </geometry>
      <material
        name="">
        <color
          rgba="1 1 1 1" />
      </material>
    </visual>
    <collision>
      <origin
        xyz="0 0 0"
        rpy="0 0 0" />
      <geometry>
        <mesh
          filename="package://panda_description/meshes/l211.STL" />
      </geometry>
    </collision>
  </link>
  <joint
    name="j211"
    type="continuous">
    <origin
      xyz="-0.0233 -0.0594 0.0264"
      rpy="1.5708 1.5708 0" />
    <parent
      link="l21" />
    <child
      link="l211" />
    <axis
      xyz="-1 0 0" />
  </joint>
  <link
    name="l2111">
    <inertial>
      <origin
        xyz="0.0254901816398352 -0.143524743603395 -0.069404695339591"
        rpy="0 0 0" />
      <mass
        value="1.25572837218662" />
      <inertia
        ixx="0.0112929247082814"
        ixy="2.17313539426183E-05"
        ixz="1.04994846003753E-05"
        iyy="0.0024380831661178"
        iyz="-0.00442427355366777"
        izz="0.00916575076151427" />
    </inertial>
    <visual>
      <origin
        xyz="0 0 0"
        rpy="0 0 0" />
      <geometry>
        <mesh
          filename="package://panda_description/meshes/l2111.STL" />
      </geometry>
      <material
        name="">
        <color
          rgba="0.333333333333333 0.333333333333333 0.333333333333333 1" />
      </material>
    </visual>
    <collision>
      <origin
        xyz="0 0 0"
        rpy="0 0 0" />
      <geometry>
        <mesh
          filename="package://panda_description/meshes/l2111.STL" />
      </geometry>
    </collision>
  </link>
  <joint
    name="j2111"
    type="continuous">
    <origin
      xyz="0 -0.15201 0.12997"
      rpy="0 0 0" />
    <parent
      link="l211" />
    <child
      link="l2111" />
    <axis
      xyz="-1 0 0" />
  </joint>
  <link
    name="l3">
    <inertial>
      <origin
        xyz="-0.0160000876283128 0.000737036465387864 0.0261570929046675"
        rpy="0 0 0" />
      <mass
        value="0.512324909923603" />
      <inertia
        ixx="0.000107100908138004"
        ixy="0"
        ixz="0"
        iyy="8.38648309010006E-05"
        iyz="0"
        izz="7.86994452918464E-05" />
    </inertial>
    <visual>
      <origin
        xyz="0 0 0"
        rpy="0 0 0" />
      <geometry>
        <mesh
          filename="package://panda_description/meshes/l3.STL" />
      </geometry>
      <material
        name="">
        <color
          rgba="0.247058823529412 0.525490196078431 1 1" />
      </material>
    </visual>
    <collision>
      <origin
        xyz="0 0 0"
        rpy="0 0 0" />
      <geometry>
        <mesh
          filename="package://panda_description/meshes/l3.STL" />
      </geometry>
    </collision>
  </link>
  <joint
    name="j3"
    type="prismatic">
    <origin
      xyz="1.3491 -0.68953 0.2649"
      rpy="1.5708 0 -3.1416" />
    <parent
      link="base_link" />
    <child
      link="l3" />
    <axis
      xyz="-1 0 0" />
    <limit
      lower="-0.111"
      upper="0.008"
      effort="100"
      velocity="1" />
  </joint>
  <link
    name="l31">
    <inertial>
      <origin
        xyz="-0.0232999999999994 -0.0383054567028329 0.000879463367712385"
        rpy="0 0 0" />
      <mass
        value="0.346974608756837" />
      <inertia
        ixx="8.66399512887479E-05"
        ixy="1.75405327974961E-20"
        ixz="2.38725309080984E-20"
        iyy="7.91945845868077E-05"
        iyz="2.40848329109915E-20"
        izz="7.11734259202268E-05" />
    </inertial>
    <visual>
      <origin
        xyz="0 0 0"
        rpy="0 0 0" />
      <geometry>
        <mesh
          filename="package://panda_description/meshes/l31.STL" />
      </geometry>
      <material
        name="">
        <color
          rgba="0.266666666666667 0.529411764705882 1 1" />
      </material>
    </visual>
    <collision>
      <origin
        xyz="0 0 0"
        rpy="0 0 0" />
      <geometry>
        <mesh
          filename="package://panda_description/meshes/l31.STL" />
      </geometry>
    </collision>
  </link>
  <joint
    name="j31"
    type="continuous">
    <origin
      xyz="-0.016 0.0199 0.055"
      rpy="3.1416 0 1.5708" />
    <parent
      link="l3" />
    <child
      link="l31" />
    <axis
      xyz="-1 0 0" />
  </joint>
  <link
    name="l311">
    <inertial>
      <origin
        xyz="-0.0259999999999999 -0.0760041259902766 0.0649874821212069"
        rpy="0 0 0" />
      <mass
        value="0.675776067601477" />
      <inertia
        ixx="0.00243508708358433"
        ixy="1.04563584276046E-18"
        ixz="9.18403266866058E-19"
        iyy="0.00150990083615139"
        iyz="0.00115453599507958"
        izz="0.00187296482245536" />
    </inertial>
    <visual>
      <origin
        xyz="0 0 0"
        rpy="0 0 0" />
      <geometry>
        <mesh
          filename="package://panda_description/meshes/l311.STL" />
      </geometry>
      <material
        name="">
        <color
          rgba="1 1 1 1" />
      </material>
    </visual>
    <collision>
      <origin
        xyz="0 0 0"
        rpy="0 0 0" />
      <geometry>
        <mesh
          filename="package://panda_description/meshes/l311.STL" />
      </geometry>
    </collision>
  </link>
  <joint
    name="j311"
    type="continuous">
    <origin
      xyz="-0.0233 -0.055 -0.0254"
      rpy="1.5708 1.5708 0" />
    <parent
      link="l31" />
    <child
      link="l311" />
    <axis
      xyz="-1 0 0" />
  </joint>
  <link
    name="l3111">
    <inertial>
      <origin
        xyz="-0.0265098183601649 -0.143524743603395 -0.0694046953395908"
        rpy="0 0 0" />
      <mass
        value="1.25572837218663" />
      <inertia
        ixx="0.0112929247082815"
        ixy="2.17313539426252E-05"
        ixz="1.04994846003767E-05"
        iyy="0.00243808316611781"
        iyz="-0.00442427355366779"
        izz="0.00916575076151432" />
    </inertial>
    <visual>
      <origin
        xyz="0 0 0"
        rpy="0 0 0" />
      <geometry>
        <mesh
          filename="package://panda_description/meshes/l3111.STL" />
      </geometry>
      <material
        name="">
        <color
          rgba="1 1 1 1" />
      </material>
    </visual>
    <collision>
      <origin
        xyz="0 0 0"
        rpy="0 0 0" />
      <geometry>
        <mesh
          filename="package://panda_description/meshes/l3111.STL" />
      </geometry>
    </collision>
  </link>
  <joint
    name="j3111"
    type="continuous">
    <origin
      xyz="0 -0.15201 0.12997"
      rpy="0 0 0" />
    <parent
      link="l311" />
    <child
      link="l3111" />
    <axis
      xyz="-1 0 0" />
  </joint>
  <link
    name="l4">
    <inertial>
      <origin
        xyz="-0.0160000876283128 0.000737036465387864 0.0261570929046675"
        rpy="0 0 0" />
      <mass
        value="0.512324909923603" />
      <inertia
        ixx="0.000107100908138004"
        ixy="0"
        ixz="0"
        iyy="8.38648309010006E-05"
        iyz="0"
        izz="7.86994452918464E-05" />
    </inertial>
    <visual>
      <origin
        xyz="0 0 0"
        rpy="0 0 0" />
      <geometry>
        <mesh
          filename="package://panda_description/meshes/l4.STL" />
      </geometry>
      <material
        name="">
        <color
          rgba="1 1 1 1" />
      </material>
    </visual>
    <collision>
      <origin
        xyz="0 0 0"
        rpy="0 0 0" />
      <geometry>
        <mesh
          filename="package://panda_description/meshes/l4.STL" />
      </geometry>
    </collision>
  </link>
  <joint
    name="j4"
    type="prismatic">
    <origin
      xyz="1.1071 -0.68953 0.2649"
      rpy="1.5708 0 -3.1416" />
    <parent
      link="base_link" />
    <child
      link="l4" />
    <axis
      xyz="-1 0 0" />
    <limit
      lower="-0.008"
      upper="0.111"
      effort="100"
      velocity="1" />
  </joint>
  <link
    name="l41">
    <inertial>
      <origin
        xyz="-0.0233 -0.038305 0.00087946"
        rpy="0 0 0" />
      <mass
        value="0.34697" />
      <inertia
        ixx="8.664E-05"
        ixy="-2.7058E-20"
        ixz="-1.6655E-20"
        iyy="7.9195E-05"
        iyz="1.1689E-20"
        izz="7.1173E-05" />
    </inertial>
    <visual>
      <origin
        xyz="0 0 0"
        rpy="0 0 0" />
      <geometry>
        <mesh
          filename="package://panda_description/meshes/l41.STL" />
      </geometry>
      <material
        name="">
        <color
          rgba="0.26667 0.52941 1 1" />
      </material>
    </visual>
    <collision>
      <origin
        xyz="0 0 0"
        rpy="0 0 0" />
      <geometry>
        <mesh
          filename="package://panda_description/meshes/l41.STL" />
      </geometry>
    </collision>
  </link>
  <joint
    name="j41"
    type="continuous">
    <origin
      xyz="-0.016 0.0199 0.055"
      rpy="3.1416 0 1.5708" />
    <parent
      link="l4" />
    <child
      link="l41" />
    <axis
      xyz="-1 0 0" />
  </joint>
  <link
    name="l411">
    <inertial>
      <origin
        xyz="0.026 -0.076004 -0.064987"
        rpy="0 0 0" />
      <mass
        value="0.67578" />
      <inertia
        ixx="0.0024351"
        ixy="-9.4141E-19"
        ixz="1.177E-18"
        iyy="0.0015099"
        iyz="-0.0011545"
        izz="0.001873" />
    </inertial>
    <visual>
      <origin
        xyz="0 0 0"
        rpy="0 3.1416 0" />
      <geometry>
        <mesh
          filename="package://panda_description/meshes/l411.STL" />
      </geometry>
      <material
        name="">
        <color
          rgba="1 1 1 1" />
      </material>
    </visual>
    <collision>
      <origin
        xyz="0 0 0"
        rpy="0 3.1416 0" />
      <geometry>
        <mesh
          filename="package://panda_description/meshes/l411.STL" />
      </geometry>
    </collision>
  </link>
  <joint
    name="j411"
    type="continuous">
    <origin
      xyz="-0.0233 -0.055 0.0274"
      rpy="1.5708 1.5708 0" />
    <parent
      link="l41" />
    <child
      link="l411" />
    <axis
      xyz="-1 0 0" />
  </joint>
  <link
    name="l4111">
    <inertial>
      <origin
        xyz="-0.02651 -0.14352 -0.069405"
        rpy="0 0 0" />
      <mass
        value="1.2557" />
      <inertia
        ixx="0.011293"
        ixy="2.1731E-05"
        ixz="1.0499E-05"
        iyy="0.0024381"
        iyz="-0.0044243"
        izz="0.0091658" />
    </inertial>
    <visual>
      <origin
        xyz="0 0 0"
        rpy="0 0 0" />
      <geometry>
        <mesh
          filename="package://panda_description/meshes/l4111.STL" />
      </geometry>
      <material
        name="">
        <color
          rgba="0.33333 0.33333 0.33333 1" />
      </material>
    </visual>
    <collision>
      <origin
        xyz="0 0 0"
        rpy="0 0 0" />
      <geometry>
        <mesh
          filename="package://panda_description/meshes/l4111.STL" />
      </geometry>
    </collision>
  </link>
  <joint
    name="j4111"
    type="continuous">
    <origin
      xyz="0 -0.15201 0.12997"
      rpy="0 0 0" />
    <parent
      link="l411" />
    <child
      link="l4111" />
    <axis
      xyz="-1 0 0" />
  </joint>

  <!-- Transmissions for Leg 1 -->
  <transmission name="j1_trans">
    <type>transmission_interface/SimpleTransmission</type>
    <joint name="j1">
      <hardwareInterface>hardware_interface/EffortJointInterface</hardwareInterface>
    </joint>
    <actuator name="j1_motor">
      <hardwareInterface>hardware_interface/EffortJointInterface</hardwareInterface>
      <mechanicalReduction>1</mechanicalReduction>
    </actuator>
  </transmission>
  <transmission name="j11_trans">
    <type>transmission_interface/SimpleTransmission</type>
    <joint name="j11">
      <hardwareInterface>hardware_interface/EffortJointInterface</hardwareInterface>
    </joint>
    <actuator name="j11_motor">
      <hardwareInterface>hardware_interface/EffortJointInterface</hardwareInterface>
      <mechanicalReduction>1</mechanicalReduction>
    </actuator>
  </transmission>
  <transmission name="j111_trans">
    <type>transmission_interface/SimpleTransmission</type>
    <joint name="j111">
      <hardwareInterface>hardware_interface/EffortJointInterface</hardwareInterface>
    </joint>
    <actuator name="j111_motor">
      <hardwareInterface>hardware_interface/EffortJointInterface</hardwareInterface>
      <mechanicalReduction>1</mechanicalReduction>
    </actuator>
  </transmission>
  <transmission name="j1111_trans">
    <type>transmission_interface/SimpleTransmission</type>
    <joint name="j1111">
      <hardwareInterface>hardware_interface/EffortJointInterface</hardwareInterface>
    </joint>
    <actuator name="j1111_motor">
      <hardwareInterface>hardware_interface/EffortJointInterface</hardwareInterface>
      <mechanicalReduction>1</mechanicalReduction>
    </actuator>
  </transmission>

  <!-- Transmissions for Leg 2 -->
  <transmission name="j2_trans">
    <type>transmission_interface/SimpleTransmission</type>
    <joint name="j2">
      <hardwareInterface>hardware_interface/EffortJointInterface</hardwareInterface>
    </joint>
    <actuator name="j2_motor">
      <hardwareInterface>hardware_interface/EffortJointInterface</hardwareInterface>
      <mechanicalReduction>1</mechanicalReduction>
    </actuator>
  </transmission>
  <transmission name="j21_trans">
    <type>transmission_interface/SimpleTransmission</type>
    <joint name="j21">
      <hardwareInterface>hardware_interface/EffortJointInterface</hardwareInterface>
    </joint>
    <actuator name="j21_motor">
      <hardwareInterface>hardware_interface/EffortJointInterface</hardwareInterface>
      <mechanicalReduction>1</mechanicalReduction>
    </actuator>
  </transmission>
  <transmission name="j211_trans">
    <type>transmission_interface/SimpleTransmission</type>
    <joint name="j211">
      <hardwareInterface>hardware_interface/EffortJointInterface</hardwareInterface>
    </joint>
    <actuator name="j211_motor">
      <hardwareInterface>hardware_interface/EffortJointInterface</hardwareInterface>
      <mechanicalReduction>1</mechanicalReduction>
    </actuator>
  </transmission>
  <transmission name="j2111_trans">
    <type>transmission_interface/SimpleTransmission</type>
    <joint name="j2111">
      <hardwareInterface>hardware_interface/EffortJointInterface</hardwareInterface>
    </joint>
    <actuator name="j2111_motor">
      <hardwareInterface>hardware_interface/EffortJointInterface</hardwareInterface>
      <mechanicalReduction>1</mechanicalReduction>
    </actuator>
  </transmission>

  <!-- Transmissions for Leg 3 -->
  <transmission name="j3_trans">
    <type>transmission_interface/SimpleTransmission</type>
    <joint name="j3">
      <hardwareInterface>hardware_interface/EffortJointInterface</hardwareInterface>
    </joint>
    <actuator name="j3_motor">
      <hardwareInterface>hardware_interface/EffortJointInterface</hardwareInterface>
      <mechanicalReduction>1</mechanicalReduction>
    </actuator>
  </transmission>
  <transmission name="j31_trans">
    <type>transmission_interface/SimpleTransmission</type>
    <joint name="j31">
      <hardwareInterface>hardware_interface/EffortJointInterface</hardwareInterface>
    </joint>
    <actuator name="j31_motor">
      <hardwareInterface>hardware_interface/EffortJointInterface</hardwareInterface>
      <mechanicalReduction>1</mechanicalReduction>
    </actuator>
  </transmission>
  <transmission name="j311_trans">
    <type>transmission_interface/SimpleTransmission</type>
    <joint name="j311">
      <hardwareInterface>hardware_interface/EffortJointInterface</hardwareInterface>
    </joint>
    <actuator name="j311_motor">
      <hardwareInterface>hardware_interface/EffortJointInterface</hardwareInterface>
      <mechanicalReduction>1</mechanicalReduction>
    </actuator>
  </transmission>
  <transmission name="j3111_trans">
    <type>transmission_interface/SimpleTransmission</type>
    <joint name="j3111">
      <hardwareInterface>hardware_interface/EffortJointInterface</hardwareInterface>
    </joint>
    <actuator name="j3111_motor">
      <hardwareInterface>hardware_interface/EffortJointInterface</hardwareInterface>
      <mechanicalReduction>1</mechanicalReduction>
    </actuator>
  </transmission>

  <!-- Transmissions for Leg 4 -->
  <transmission name="j4_trans">
    <type>transmission_interface/SimpleTransmission</type>
    <joint name="j4">
      <hardwareInterface>hardware_interface/EffortJointInterface</hardwareInterface>
    </joint>
    <actuator name="j4_motor">
      <hardwareInterface>hardware_interface/EffortJointInterface</hardwareInterface>
      <mechanicalReduction>1</mechanicalReduction>
    </actuator>
  </transmission>
  <transmission name="j41_trans">
    <type>transmission_interface/SimpleTransmission</type>
    <joint name="j41">
      <hardwareInterface>hardware_interface/EffortJointInterface</hardwareInterface>
    </joint>
    <actuator name="j41_motor">
      <hardwareInterface>hardware_interface/EffortJointInterface</hardwareInterface>
      <mechanicalReduction>1</mechanicalReduction>
    </actuator>
  </transmission>
  <transmission name="j411_trans">
    <type>transmission_interface/SimpleTransmission</type>
    <joint name="j411">
      <hardwareInterface>hardware_interface/EffortJointInterface</hardwareInterface>
    </joint>
    <actuator name="j411_motor">
      <hardwareInterface>hardware_interface/EffortJointInterface</hardwareInterface>
      <mechanicalReduction>1</mechanicalReduction>
    </actuator>
  </transmission>
  <transmission name="j4111_trans">
    <type>transmission_interface/SimpleTransmission</type>
    <joint name="j4111">
      <hardwareInterface>hardware_interface/EffortJointInterface</hardwareInterface>
    </joint>
    <actuator name="j4111_motor">
      <hardwareInterface>hardware_interface/EffortJointInterface</hardwareInterface>
      <mechanicalReduction>1</mechanicalReduction>
    </actuator>
  </transmission>

  <gazebo>
    <plugin name="gazebo_ros_control" filename="libgazebo_ros_control.so">
      <robotNamespace>/</robotNamespace>
    </plugin>
  </gazebo>
</robot>
