<?xml version="1.0"?>
<!--
  Dog2 Robot Description (Xacro Source)
  
  This file defines the Dog2 quadruped robot with parameterized joint limits.
  All configuration is in this single file for simplicity.
  
  INERTIA CORRECTIONS APPLIED:
  - Leg 3 & 4 (thigh + shin): Corrected to negative X coordinates (mirrored geometry)
  - Based on correct URDF file
  - Date: 2026-01-27
  
  SPHERICAL FEET ADDED:
  - Each leg now has a 5th link (foot) with spherical geometry
  - Radius: 0.02m, Mass: 0.05kg
  - Date: 2026-01-28
  
  JOINT LIMITS:
  - Hip joints: ±150° (±2.618 rad)
  - Knee joints: ±160° (±2.8 rad)
-->
<robot xmlns:xacro="http://www.ros.org/wiki/xacro" name="dog2">

  <!-- ============================================ -->
  <!-- SECTION 1: PROPERTY DEFINITIONS              -->
  <!-- ============================================ -->
  
  <xacro:arg name="controllers_yaml" default=""/>
  
  <!-- Hip joint limits: ±150° (±2.618 rad) for obstacle crossing -->
  <xacro:property name="hip_lower_limit" value="-2.618"/>
  <xacro:property name="hip_upper_limit" value="2.618"/>
  <xacro:property name="hip_effort" value="50"/>
  <xacro:property name="hip_velocity" value="20"/>

  <!-- Knee joint limits: ±160° (±2.8 rad) for bidirectional folding -->
  <xacro:property name="knee_lower_limit" value="-1.3"/>
  <xacro:property name="knee_upper_limit" value="2.8"/>
  <xacro:property name="knee_effort" value="50"/>
  <xacro:property name="knee_velocity" value="20"/>

  <!-- Prismatic joint limits -->
  <xacro:property name="prismatic_effort" value="100"/>
  <xacro:property name="prismatic_velocity" value="5"/>

  <!-- ============================================ -->
  <!-- INERTIA PROPERTIES                           -->
  <!-- ============================================ -->
  
  <!-- Leg 1 & 2 inertia (front legs, positive X) -->
  <xacro:property name="leg12_thigh_inertia_xyz" value="0.026 -0.0760041259902766 0.0649874821212071"/>
  <xacro:property name="leg12_shin_inertia_xyz" value="0.0254901816398352 -0.143524743603395 -0.0694046953395906"/>

  <!-- Leg 3 inertia (rear left, negative X - mirrored) -->
  <xacro:property name="leg3_thigh_inertia_xyz" value="-0.0259999999999999 -0.0760041259902766 0.0649874821212069"/>
  <xacro:property name="leg3_shin_inertia_xyz" value="-0.0265098183601649 -0.143524743603395 -0.0694046953395908"/>

  <!-- Leg 4 inertia (rear right, negative X - mirrored) -->
  <xacro:property name="leg4_thigh_inertia_xyz" value="-0.026 -0.0760041259902766 0.0649874821212069"/>
  <xacro:property name="leg4_shin_inertia_xyz" value="-0.0265089672547710 -0.1429895138560395 -0.0691152554666486"/>

  <!-- ============================================ -->
  <!-- WORLD AND BASE LINKS                         -->
  <!-- ============================================ -->
  
  <!-- Base link (main body) -->
  <link name="base_link">
    <inertial>
      <origin xyz="1.2222277650107181 -0.7494824107130249 0.2604663063045544" rpy="1.5708 0 0"/>
      <mass value="6.0" />
      <inertia
        ixx="0.0153"
        ixy="0.00011"
        ixz="0"
        iyy="0.052"
        iyz="0"
        izz="0.044" />
    </inertial>
    <visual>
      <origin xyz="0 0 0" rpy="0 0 0" />
      <geometry>
        <mesh filename="package://dog2_description/meshes/base_link.STL" />
      </geometry>
      <material name="">
        <color rgba="0.752941176470588 0.752941176470588 0.752941176470588 1" />
      </material>
    </visual>
    <collision>
      <origin xyz="0.058758 -0.037411 0.015228" rpy="0 0 0" />
      <geometry>
        <mesh filename="package://dog2_description/meshes/collision/base_link_collision.STL" scale="0.95 0.95 0.95" />
      </geometry>
    </collision>
  </link>

  <!-- ============================================ -->
  <!-- SECTION 2: LEG MACRO DEFINITION              -->
  <!-- ============================================ -->
  
  <xacro:macro name="leg" params="prefix leg_num origin_xyz origin_rpy prismatic_lower prismatic_upper
                                 thigh_inertia_xyz shin_inertia_xyz
                                 prismatic_inertia_xyz:='-0.0159999123716776 0.000737036465389251 0.0261570925915838'
                                 hip_joint_rpy:='0 0 1.5708'
                                 hip_joint_xyz:='-0.016 0.0199 0.055'
                                 knee_joint_xyz:='-0.0233 -0.055 0.0274'
                                 thigh_visual_rpy:='0 0 0'
                                 thigh_collision_rpy:='0 0 0'
                                 foot_xyz:='-0.034 -0.299478 -0.12'">

  <!-- Prismatic link (l${leg_num}) -->
  <link name="l${leg_num}">
    <inertial>
      <origin rpy="0 0 0" xyz="${prismatic_inertia_xyz}"/>
      <mass value="0.3"/>
      <inertia ixx="0.000107100908138004" ixy="0" ixz="0" iyy="8.38648309010005E-05" iyz="0" izz="7.86994452918461E-05"/>
    </inertial>
    <visual>
      <origin rpy="0 0 0" xyz="0 0 0"/>
      <geometry>
        <mesh filename="package://dog2_description/meshes/l${leg_num}.STL"/>
      </geometry>
      <material name="">
        <color rgba="1 1 1 1"/>
      </material>
    </visual>
    <collision>
      <origin rpy="0 0 0" xyz="0 0 0"/>
      <geometry>
        <mesh filename="package://dog2_description/meshes/collision/l${leg_num}_collision.STL" scale="0.8 0.8 0.8"/>
      </geometry>
    </collision>
  </link>
  
  <!-- Prismatic joint (j${leg_num}) -->
  <joint name="j${leg_num}" type="prismatic">
    <origin rpy="${origin_rpy}" xyz="${origin_xyz}"/>
    <parent link="base_link"/>
    <child link="l${leg_num}"/>
    <axis xyz="-1 0 0"/>
    <limit effort="${prismatic_effort}" lower="${prismatic_lower}" upper="${prismatic_upper}" velocity="${prismatic_velocity}"/>
  </joint>
  
  <!-- Hip link (${prefix}_hip_link) -->
  <link name="${prefix}_hip_link">
    <inertial>
      <origin rpy="0 0 0" xyz="-0.0233000000000003 -0.038305456702832 0.000879463367713051"/>
      <mass value="0.25"/>
      <inertia ixx="0.0001" ixy="0" ixz="0" iyy="0.0001" iyz="0" izz="0.0001"/>
    </inertial>
    <visual>
      <origin rpy="0 0 0" xyz="0 0 0"/>
      <geometry>
        <mesh filename="package://dog2_description/meshes/l${leg_num}1.STL"/>
      </geometry>
      <material name="">
        <color rgba="0.266666666666667 0.529411764705882 1 1"/>
      </material>
    </visual>
    <collision>
      <origin rpy="0 0 0" xyz="0 0 0"/>
      <geometry>
        <mesh filename="package://dog2_description/meshes/collision/l${leg_num}1_collision.STL" scale="0.8 0.8 0.8"/>
      </geometry>
    </collision>
  </link>
  
  <!-- Hip joint (${prefix}_haa_joint) - HAA: Hip Abduction/Adduction -->
  <joint name="${prefix}_haa_joint" type="revolute">
    <origin rpy="${hip_joint_rpy}" xyz="${hip_joint_xyz}"/>
    <parent link="l${leg_num}"/>
    <child link="${prefix}_hip_link"/>
    <axis xyz="0 1 0"/>
    <limit effort="${hip_effort}" lower="${hip_lower_limit}" upper="${hip_upper_limit}" velocity="${hip_velocity}"/>
  </joint>
  
  <!-- Thigh link (${prefix}_upper_leg_link) -->
  <link name="${prefix}_upper_leg_link">
    <inertial>
      <origin rpy="0 0 0" xyz="${thigh_inertia_xyz}"/>
      <mass value="0.4"/>
      <inertia ixx="0.000666" ixy="0" ixz="0" iyy="0.000356" iyz="0.000266" izz="0.000534"/>
    </inertial>
    <visual>
      <origin rpy="${thigh_visual_rpy}" xyz="0 0 0"/>
      <geometry>
        <mesh filename="package://dog2_description/meshes/l${leg_num}11.STL"/>
      </geometry>
      <material name="">
        <color rgba="1 1 1 1"/>
      </material>
    </visual>
    <collision>
      <origin rpy="${thigh_collision_rpy}" xyz="0 0 0"/>
      <geometry>
        <mesh filename="package://dog2_description/meshes/collision/l${leg_num}11_collision.STL" scale="0.8 0.8 0.8"/>
      </geometry>
    </collision>
  </link>
  
  <!-- Hip flexion/extension joint (HFE) (j${leg_num}11) -->
  <joint name="${prefix}_hfe_joint" type="revolute">
    <origin rpy="1.5708 1.5708 0" xyz="${knee_joint_xyz}"/>
    <parent link="${prefix}_hip_link"/>
    <child link="${prefix}_upper_leg_link"/>
    <axis xyz="-1 0 0"/>
    <limit effort="${knee_effort}" lower="${knee_lower_limit}" upper="${knee_upper_limit}" velocity="${knee_velocity}"/>
  </joint>
  
  <!-- Shin link (${prefix}_lower_leg_link) -->
  <link name="${prefix}_lower_leg_link">
    <inertial>
      <origin rpy="0 0 0" xyz="${shin_inertia_xyz}"/>
      <mass value="0.5"/>
      <inertia ixx="0.004517" ixy="0.00000870" ixz="0.00000420" iyy="0.000975" iyz="-0.00176971" izz="0.003666"/>
    </inertial>
    <visual>
      <origin rpy="0 0 0" xyz="0 0 0"/>
      <geometry>
        <mesh filename="package://dog2_description/meshes/l${leg_num}111.STL"/>
      </geometry>
      <material name="">
        <color rgba="1 1 1 1"/>
      </material>
    </visual>
    <collision>
      <origin rpy="0 0 0" xyz="0 0 0"/>
      <geometry>
        <mesh filename="package://dog2_description/meshes/collision/l${leg_num}111_collision.STL" scale="0.8 0.8 0.8"/>
      </geometry>
    </collision>
  </link>
  
  <!-- Knee joint (KFE) (j${leg_num}111) -->
  <joint name="${prefix}_kfe_joint" type="revolute">
    <origin rpy="0 0 0" xyz="0 -0.15201 0.12997"/>
    <parent link="${prefix}_upper_leg_link"/>
    <child link="${prefix}_lower_leg_link"/>
    <axis xyz="-1 0 0"/>
    <limit effort="${knee_effort}" lower="${knee_lower_limit}" upper="${knee_upper_limit}" velocity="${knee_velocity}"/>
  </joint>
  
  <!-- Gazebo friction configuration for shin link -->
  <gazebo reference="${prefix}_lower_leg_link">
    <mu1>1.0</mu1>
    <mu2>1.0</mu2>
    <kp>1000000.0</kp>
    <kd>100.0</kd>
    <minDepth>0.001</minDepth>
    <maxVel>0.1</maxVel>
    <material>Gazebo/Grey</material>
  </gazebo>
  
  <!-- Foot link (l${leg_num}1111) - Spherical geometry -->
  <link name="${prefix}_foot_link">
    <inertial>
      <origin rpy="0 0 0" xyz="0 0 0"/>
      <mass value="0.05"/>
      <inertia ixx="8e-6" ixy="0" ixz="0" iyy="8e-6" iyz="0" izz="8e-6"/>
    </inertial>
    <visual>
      <origin rpy="0 0 0" xyz="0 0 0"/>
      <geometry>
        <sphere radius="0.02"/>
      </geometry>
      <material name="">
        <color rgba="0.5 0.5 0.5 1"/>
      </material>
    </visual>
    <collision>
      <origin rpy="0 0 0" xyz="0 0 0"/>
      <geometry>
        <sphere radius="0.02"/>
      </geometry>
    </collision>
  </link>
  
  <!-- Fixed joint connecting shin to foot (${prefix}_foot_fixed_joint) -->
  <joint name="${prefix}_foot_fixed_joint" type="fixed">
    <origin rpy="0 0 0" xyz="${foot_xyz}"/>
    <parent link="${prefix}_lower_leg_link"/>
    <child link="${prefix}_foot_link"/>
  </joint>
  
  <!-- Gazebo friction configuration for foot link -->
  <gazebo reference="${prefix}_foot_link">
    <mu1>1.5</mu1>
    <mu2>1.5</mu2>
    <kp>1000000.0</kp>
    <kd>100.0</kd>
    <minDepth>0.001</minDepth>
    <maxVel>0.1</maxVel>
    <material>Gazebo/Grey</material>
  </gazebo>

  </xacro:macro>

  <!-- ============================================ -->
  <!-- SECTION 3: LEG INSTANTIATIONS                -->
  <!-- ============================================ -->

  <!-- Leg 1: Front Left -->
  <xacro:leg prefix="lf" leg_num="1" 
             origin_xyz="1.1026 -0.80953 0.2649" 
             origin_rpy="1.5708 0 0" 
             prismatic_lower="-0.111" 
             prismatic_upper="0.0"
             thigh_inertia_xyz="${leg12_thigh_inertia_xyz}"
             shin_inertia_xyz="${leg12_shin_inertia_xyz}"
             foot_xyz="0.026 -0.289478 -0.14"/>

  <!-- Leg 2: Front Right -->
  <xacro:leg prefix="rf" leg_num="2" 
             origin_xyz="1.3491 -0.80953 0.2649" 
             origin_rpy="1.5708 0 0" 
             prismatic_lower="-0.0" 
             prismatic_upper="0.111"
             thigh_inertia_xyz="${leg12_thigh_inertia_xyz}"
             shin_inertia_xyz="${leg12_shin_inertia_xyz}"
             prismatic_inertia_xyz="0.0159999141740211 0.0007376899322864 0.0261433571319548"
             hip_joint_xyz="0.0116 0.0199 0.055"
             foot_xyz="0.026 -0.289478 -0.14"/>

  <!-- Leg 3: Rear Left (with inertia corrections for mirrored geometry) -->
  <xacro:leg prefix="lh" leg_num="3" 
             origin_xyz="1.3491 -0.68953 0.2649" 
             origin_rpy="1.5708 0 -3.1416" 
             prismatic_lower="-0.111" 
             prismatic_upper="0.0"
             thigh_inertia_xyz="${leg3_thigh_inertia_xyz}"
             shin_inertia_xyz="${leg3_shin_inertia_xyz}"
             hip_joint_rpy="3.1416 0 1.5708"
             knee_joint_xyz="-0.0233 -0.055 -0.0254"
             foot_xyz="-0.0286 -0.289478 -0.14"/>

  <!-- Leg 4: Rear Right (with inertia corrections for mirrored geometry) -->
  <xacro:leg prefix="rh" leg_num="4" 
             origin_xyz="1.1071 -0.68953 0.2649" 
             origin_rpy="1.5708 0 -3.1416" 
             prismatic_lower="-0.0" 
             prismatic_upper="0.111"
             thigh_inertia_xyz="${leg4_thigh_inertia_xyz}"
             shin_inertia_xyz="${leg4_shin_inertia_xyz}"
             prismatic_inertia_xyz="0.0159999183367299 0.0007376902203368 0.0261433564499887"
             hip_joint_rpy="3.1416 0 1.5708"
             hip_joint_xyz="0.0116 0.0199 0.055"
             knee_joint_xyz="-0.0233 -0.055 -0.0254"
             thigh_visual_rpy="0 3.1416 0"
             thigh_collision_rpy="0 3.1416 0"
             foot_xyz="-0.0286 -0.289478 -0.14"/>

  <!-- ============================================ -->
  <!-- SECTION 4: ROS 2 CONTROL & GAZEBO            -->
  <!-- ============================================ -->
  <ros2_control name="GazeboSystem" type="system">
    <hardware>
      <plugin>gz_ros2_control/GazeboSimSystem</plugin>
    </hardware>
    
    <!-- Leg 1 Joints -->
    <joint name="j1">
      <command_interface name="position"/>
      <state_interface name="position"/>
      <state_interface name="velocity"/>
    </joint>
    <joint name="j11">
      <command_interface name="position"/>
      <state_interface name="position"/>
      <state_interface name="velocity"/>
    </joint>
    <joint name="j111">
      <command_interface name="position"/>
      <state_interface name="position"/>
      <state_interface name="velocity"/>
    </joint>
    <joint name="j1111">
      <command_interface name="position"/>
      <state_interface name="position"/>
      <state_interface name="velocity"/>
    </joint>
    
    <!-- Leg 2 Joints -->
    <joint name="j2">
      <command_interface name="position"/>
      <state_interface name="position"/>
      <state_interface name="velocity"/>
    </joint>
    <joint name="j21">
      <command_interface name="position"/>
      <state_interface name="position"/>
      <state_interface name="velocity"/>
    </joint>
    <joint name="j211">
      <command_interface name="position"/>
      <state_interface name="position"/>
      <state_interface name="velocity"/>
    </joint>
    <joint name="j2111">
      <command_interface name="position"/>
      <state_interface name="position"/>
      <state_interface name="velocity"/>
    </joint>
    
    <!-- Leg 3 Joints -->
    <joint name="j3">
      <command_interface name="position"/>
      <state_interface name="position"/>
      <state_interface name="velocity"/>
    </joint>
    <joint name="j31">
      <command_interface name="position"/>
      <state_interface name="position"/>
      <state_interface name="velocity"/>
    </joint>
    <joint name="j311">
      <command_interface name="position"/>
      <state_interface name="position"/>
      <state_interface name="velocity"/>
    </joint>
    <joint name="j3111">
      <command_interface name="position"/>
      <state_interface name="position"/>
      <state_interface name="velocity"/>
    </joint>
    
    <!-- Leg 4 Joints -->
    <joint name="j4">
      <command_interface name="position"/>
      <state_interface name="position"/>
      <state_interface name="velocity"/>
    </joint>
    <joint name="j41">
      <command_interface name="position"/>
      <state_interface name="position"/>
      <state_interface name="velocity"/>
    </joint>
    <joint name="j411">
      <command_interface name="position"/>
      <state_interface name="position"/>
      <state_interface name="velocity"/>
    </joint>
    <joint name="j4111">
      <command_interface name="position"/>
      <state_interface name="position"/>
      <state_interface name="velocity"/>
    </joint>
  </ros2_control>
  
  <!-- Gazebo ROS 2 Control Plugin -->
  <gazebo>
    <plugin filename="gz_ros2_control-system" name="gz_ros2_control::GazeboSimROS2ControlPlugin">
      <parameters>$(arg controllers_yaml)</parameters>
      <robot_param>robot_description</robot_param>
      <robot_param_node>robot_state_publisher</robot_param_node>
    </plugin>
  </gazebo>

</robot>
